Workbook

Sheet Instructions
A1: Instructions
A2: Inventory_Management.xlsx - Instructions
A4: Sheets:
A5: - Inventory: Stock list with supplier and reorder info.
A6: Suggested tasks:
A7: - Identify low-stock items (Stock Quantity <= Reorder Point).
A8: - Use LOOKUP to pull supplier contact (create a Supplier sheet if needed).
A9: - Create a reorder report showing items to order and suggested quantities.

Sheet Inventory
A1: Item Code | B1: Item | C1: Supplier | D1: Unit Cost (£) | E1: Stock Quantity | F1: Reorder Point | G1: Lead Time (days) | H1: Low Stock | I1: Suppier Email | J1: Supplier Phone
A2: SKU200 | B2: Desk Lamp | C2: BritGoods Ltd | D2: 101.19 | E2: 172 | F2: 20 | G2: 4 | H2: =IF(E2<=F2,"YES","NO") -> NO | I2: {=IF(H2="YES",_xlfn.XLOOKUP(C2,Supplier!$A:$A,Supplier!$C:$D),"")}
A3: SKU201 | B3: Cotton Shirt | C3: BritGoods Ltd | D3: 70.34 | E3: 128 | F3: 78 | G3: 18 | H3: =IF(E3<=F3,"YES","NO") -> NO | I3: {=IF(H3="YES",_xlfn.XLOOKUP(C3,Supplier!$A:$A,Supplier!$C:$D),"")}
A4: SKU202 | B4: Wireless Mouse | C4: Crown Suppliers | D4: 59.99 | E4: 212 | F4: 40 | G4: 19 | H4: =IF(E4<=F4,"YES","NO") -> NO | I4: {=IF(H4="YES",_xlfn.XLOOKUP(C4,Supplier!$A:$A,Supplier!$C:$D),"")}
A5: SKU203 | B5: Thermal Jacket | C5: Union Parts | D5: 78.17 | E5: 72 | F5: 80 | G5: 15 | H5: =IF(E5<=F5,"YES","NO") -> YES | I5: {=IF(H5="YES",_xlfn.XLOOKUP(C5,Supplier!$A:$A,Supplier!$C:$D),"")} -> Rana.Dubey@union.com | J5: 8164557242
A6: SKU204 | B6: Desk Lamp | C6: NorthTech Supplies | D6: 73.31 | E6: 185 | F6: 28 | G6: 9 | H6: =IF(E6<=F6,"YES","NO") -> NO | I6: {=IF(H6="YES",_xlfn.XLOOKUP(C6,Supplier!$A:$A,Supplier!$C:$D),"")}
A7: SKU205 | B7: Desk Lamp | C7: BritGoods Ltd | D7: 17.41 | E7: 36 | F7: 65 | G7: 16 | H7: =IF(E7<=F7,"YES","NO") -> YES | I7: {=IF(H7="YES",_xlfn.XLOOKUP(C7,Supplier!$A:$A,Supplier!$C:$D),"")} -> Adam.Francis@britgoods.com | J7: 8707063874
A8: SKU206 | B8: Oak Desk | C8: BritGoods Ltd | D8: 13.17 | E8: 46 | F8: 21 | G8: 12 | H8: =IF(E8<=F8,"YES","NO") -> NO | I8: {=IF(H8="YES",_xlfn.XLOOKUP(C8,Supplier!$A:$A,Supplier!$C:$D),"")}
A9: SKU207 | B9: Ergo Chair | C9: NorthTech Supplies | D9: 37.34 | E9: 156 | F9: 36 | G9: 20 | H9: =IF(E9<=F9,"YES","NO") -> NO | I9: {=IF(H9="YES",_xlfn.XLOOKUP(C9,Supplier!$A:$A,Supplier!$C:$D),"")}
A10: SKU208 | B10: LED Monitor | C10: NorthTech Supplies | D10: 37 | E10: 124 | F10: 80 | G10: 19 | H10: =IF(E10<=F10,"YES","NO") -> NO | I10: {=IF(H10="YES",_xlfn.XLOOKUP(C10,Supplier!$A:$A,Supplier!$C:$D),"")}
A11: SKU209 | B11: Ergo Chair | C11: NorthTech Supplies | D11: 58.91 | E11: 157 | F11: 48 | G11: 7 | H11: =IF(E11<=F11,"YES","NO") -> NO | I11: {=IF(H11="YES",_xlfn.XLOOKUP(C11,Supplier!$A:$A,Supplier!$C:$D),"")}
A12: SKU210 | B12: Cotton Shirt | C12: Crown Suppliers | D12: 74.89 | E12: 250 | F12: 59 | G12: 11 | H12: =IF(E12<=F12,"YES","NO") -> NO | I12: {=IF(H12="YES",_xlfn.XLOOKUP(C12,Supplier!$A:$A,Supplier!$C:$D),"")}
A13: SKU211 | B13: Ergo Chair | C13: BritGoods Ltd | D13: 63.83 | E13: 50 | F13: 27 | G13: 20 | H13: =IF(E13<=F13,"YES","NO") -> NO | I13: {=IF(H13="YES",_xlfn.XLOOKUP(C13,Supplier!$A:$A,Supplier!$C:$D),"")}
A14: SKU212 | B14: X-Phone Case | C14: NorthTech Supplies | D14: 29.83 | E14: 110 | F14: 47 | G14: 16 | H14: =IF(E14<=F14,"YES","NO") -> NO | I14: {=IF(H14="YES",_xlfn.XLOOKUP(C14,Supplier!$A:$A,Supplier!$C:$D),"")}
A15: SKU213 | B15: X-Phone Case | C15: BritGoods Ltd | D15: 86.07 | E15: 15 | F15: 20 | G15: 14 | H15: =IF(E15<=F15,"YES","NO") -> YES | I15: {=IF(H15="YES",_xlfn.XLOOKUP(C15,Supplier!$A:$A,Supplier!$C:$D),"")} -> Adam.Francis@britgoods.com | J15: 8707063874
A16: SKU214 | B16: LED Monitor | C16: BritGoods Ltd | D16: 66.78 | E16: 49 | F16: 54 | G16: 15 | H16: =IF(E16<=F16,"YES","NO") -> YES | I16: {=IF(H16="YES",_xlfn.XLOOKUP(C16,Supplier!$A:$A,Supplier!$C:$D),"")} -> Adam.Francis@britgoods.com | J16: 8707063874
A17: SKU215 | B17: LED Monitor | C17: NorthTech Supplies | D17: 4.94 | E17: 161 | F17: 22 | G17: 13 | H17: =IF(E17<=F17,"YES","NO") -> NO | I17: {=IF(H17="YES",_xlfn.XLOOKUP(C17,Supplier!$A:$A,Supplier!$C:$D),"")}
A18: SKU216 | B18: Oak Desk | C18: Westfield Distributors | D18: 32.71 | E18: 135 | F18: 77 | G18: 10 | H18: =IF(E18<=F18,"YES","NO") -> NO | I18: {=IF(H18="YES",_xlfn.XLOOKUP(C18,Supplier!$A:$A,Supplier!$C:$D),"")}
A19: SKU217 | B19: X-Phone Case | C19: Westfield Distributors | D19: 68.39 | E19: 41 | F19: 79 | G19: 16 | H19: =IF(E19<=F19,"YES","NO") -> YES | I19: {=IF(H19="YES",_xlfn.XLOOKUP(C19,Supplier!$A:$A,Supplier!$C:$D),"")} -> Connor.Diabolic@westfield.com | J19: 7078282595
A20: SKU218 | B20: Oak Desk | C20: Crown Suppliers | D20: 93.12 | E20: 15 | F20: 23 | G20: 17 | H20: =IF(E20<=F20,"YES","NO") -> YES | I20: {=IF(H20="YES",_xlfn.XLOOKUP(C20,Supplier!$A:$A,Supplier!$C:$D),"")} -> Tia.McMillian@crown.com | J20: 8487915906
A21: SKU219 | B21: Cotton Shirt | C21: Crown Suppliers | D21: 85.06 | E21: 41 | F21: 72 | G21: 17 | H21: =IF(E21<=F21,"YES","NO") -> YES | I21: {=IF(H21="YES",_xlfn.XLOOKUP(C21,Supplier!$A:$A,Supplier!$C:$D),"")} -> Tia.McMillian@crown.com | J21: 8487915906
A22: SKU220 | B22: Cotton Shirt | C22: BritGoods Ltd | D22: 103.58 | E22: 45 | F22: 74 | G22: 20 | H22: =IF(E22<=F22,"YES","NO") -> YES | I22: {=IF(H22="YES",_xlfn.XLOOKUP(C22,Supplier!$A:$A,Supplier!$C:$D),"")} -> Adam.Francis@britgoods.com | J22: 8707063874
A23: SKU221 | B23: LED Monitor | C23: Crown Suppliers | D23: 74.89 | E23: 98 | F23: 63 | G23: 9 | H23: =IF(E23<=F23,"YES","NO") -> NO | I23: {=IF(H23="YES",_xlfn.XLOOKUP(C23,Supplier!$A:$A,Supplier!$C:$D),"")}
A24: SKU222 | B24: LED Monitor | C24: Union Parts | D24: 51.57 | E24: 191 | F24: 25 | G24: 19 | H24: =IF(E24<=F24,"YES","NO") -> NO | I24: {=IF(H24="YES",_xlfn.XLOOKUP(C24,Supplier!$A:$A,Supplier!$C:$D),"")}
A25: SKU223 | B25: Thermal Jacket | C25: NorthTech Supplies | D25: 106.52 | E25: 246 | F25: 54 | G25: 15 | H25: =IF(E25<=F25,"YES","NO") -> NO | I25: {=IF(H25="YES",_xlfn.XLOOKUP(C25,Supplier!$A:$A,Supplier!$C:$D),"")}
A26: SKU224 | B26: Oak Desk | C26: Union Parts | D26: 57.04 | E26: 63 | F26: 47 | G26: 20 | H26: =IF(E26<=F26,"YES","NO") -> NO | I26: {=IF(H26="YES",_xlfn.XLOOKUP(C26,Supplier!$A:$A,Supplier!$C:$D),"")}
A27: SKU225 | B27: Desk Lamp | C27: NorthTech Supplies | D27: 4.59 | E27: 19 | F27: 32 | G27: 7 | H27: =IF(E27<=F27,"YES","NO") -> YES | I27: {=IF(H27="YES",_xlfn.XLOOKUP(C27,Supplier!$A:$A,Supplier!$C:$D),"")} -> Fia.Ghazal@northtech.com | J27: 8496059877
A28: SKU226 | B28: Oak Desk | C28: BritGoods Ltd | D28: 108.46 | E28: 183 | F28: 58 | G28: 7 | H28: =IF(E28<=F28,"YES","NO") -> NO | I28: {=IF(H28="YES",_xlfn.XLOOKUP(C28,Supplier!$A:$A,Supplier!$C:$D),"")}
A29: SKU227 | B29: Ergo Chair | C29: Crown Suppliers | D29: 102.58 | E29: 187 | F29: 34 | G29: 14 | H29: =IF(E29<=F29,"YES","NO") -> NO | I29: {=IF(H29="YES",_xlfn.XLOOKUP(C29,Supplier!$A:$A,Supplier!$C:$D),"")}
A30: SKU228 | B30: Oak Desk | C30: Union Parts | D30: 89.64 | E30: 186 | F30: 74 | G30: 5 | H30: =IF(E30<=F30,"YES","NO") -> NO | I30: {=IF(H30="YES",_xlfn.XLOOKUP(C30,Supplier!$A:$A,Supplier!$C:$D),"")}
A31: SKU229 | B31: Wireless Mouse | C31: Westfield Distributors | D31: 86.3 | E31: 195 | F31: 67 | G31: 3 | H31: =IF(E31<=F31,"YES","NO") -> NO | I31: {=IF(H31="YES",_xlfn.XLOOKUP(C31,Supplier!$A:$A,Supplier!$C:$D),"")}
A32: SKU230 | B32: Cotton Shirt | C32: Union Parts | D32: 61.44 | E32: 24 | F32: 61 | G32: 4 | H32: =IF(E32<=F32,"YES","NO") -> YES | I32: {=IF(H32="YES",_xlfn.XLOOKUP(C32,Supplier!$A:$A,Supplier!$C:$D),"")} -> Rana.Dubey@union.com | J32: 8164557242
A33: SKU231 | B33: Cotton Shirt | C33: Westfield Distributors | D33: 99.85 | E33: 42 | F33: 20 | G33: 20 | H33: =IF(E33<=F33,"YES","NO") -> NO | I33: {=IF(H33="YES",_xlfn.XLOOKUP(C33,Supplier!$A:$A,Supplier!$C:$D),"")}
A34: SKU232 | B34: Ergo Chair | C34: Westfield Distributors | D34: 33.07 | E34: 19 | F34: 59 | G34: 7 | H34: =IF(E34<=F34,"YES","NO") -> YES | I34: {=IF(H34="YES",_xlfn.XLOOKUP(C34,Supplier!$A:$A,Supplier!$C:$D),"")} -> Connor.Diabolic@westfield.com | J34: 7078282595
A35: SKU233 | B35: Wireless Mouse | C35: Crown Suppliers | D35: 55.85 | E35: 104 | F35: 27 | G35: 17 | H35: =IF(E35<=F35,"YES","NO") -> NO | I35: {=IF(H35="YES",_xlfn.XLOOKUP(C35,Supplier!$A:$A,Supplier!$C:$D),"")}
A36: SKU234 | B36: Ergo Chair | C36: Westfield Distributors | D36: 116.53 | E36: 107 | F36: 57 | G36: 20 | H36: =IF(E36<=F36,"YES","NO") -> NO | I36: {=IF(H36="YES",_xlfn.XLOOKUP(C36,Supplier!$A:$A,Supplier!$C:$D),"")}
A37: SKU235 | B37: LED Monitor | C37: Crown Suppliers | D37: 84.52 | E37: 89 | F37: 62 | G37: 18 | H37: =IF(E37<=F37,"YES","NO") -> NO | I37: {=IF(H37="YES",_xlfn.XLOOKUP(C37,Supplier!$A:$A,Supplier!$C:$D),"")}
A38: SKU236 | B38: Oak Desk | C38: NorthTech Supplies | D38: 118.92 | E38: 210 | F38: 66 | G38: 7 | H38: =IF(E38<=F38,"YES","NO") -> NO | I38: {=IF(H38="YES",_xlfn.XLOOKUP(C38,Supplier!$A:$A,Supplier!$C:$D),"")}
A39: SKU237 | B39: Cotton Shirt | C39: Union Parts | D39: 47.08 | E39: 244 | F39: 72 | G39: 15 | H39: =IF(E39<=F39,"YES","NO") -> NO | I39: {=IF(H39="YES",_xlfn.XLOOKUP(C39,Supplier!$A:$A,Supplier!$C:$D),"")}
A40: SKU238 | B40: Cotton Shirt | C40: BritGoods Ltd | D40: 75.14 | E40: 90 | F40: 56 | G40: 6 | H40: =IF(E40<=F40,"YES","NO") -> NO | I40: {=IF(H40="YES",_xlfn.XLOOKUP(C40,Supplier!$A:$A,Supplier!$C:$D),"")}
...

Sheet Supplier
A1: Supplier | B1: Name | C1: Email | D1: Phone
A2: BritGoods Ltd | B2: Adam Francis | C2: Adam.Francis@britgoods.com | D2: =RANDBETWEEN(1000000000,9999999999) -> 8707063874
A3: Crown Suppliers | B3: Tia McMillian | C3: Tia.McMillian@crown.com | D3: =RANDBETWEEN(1000000000,9999999999) -> 8487915906
A4: Union Parts | B4: Rana Dubey | C4: Rana.Dubey@union.com | D4: =RANDBETWEEN(1000000000,9999999999) -> 8164557242
A5: NorthTech Supplies | B5: Fia Ghazal | C5: Fia.Ghazal@northtech.com | D5: =RANDBETWEEN(1000000000,9999999999) -> 8496059877
A6: Westfield Distributors | B6: Connor Diabolic | C6: Connor.Diabolic@westfield.com | D6: =RANDBETWEEN(1000000000,9999999999) -> 7078282595

Sheet Reorder Report
A1: Item Code | B1: Item | C1: Supplier | D1: Unit Cost (£) | E1: Stock Quantity | F1: Reorder Point | G1: Target Stock | H1: Suggested Quantity | I1: Supplier Email | J1: Supplier Phone | K1: Total Order Value
A2: {=_xlfn._xlws.FILTER(Inventory!A2:F41,Inventory!H2:H41="YES")} -> SKU203 | B2: Thermal Jacket | C2: Union Parts | D2: 78.17 | E2: 72 | F2: 80 | G2: =F2*2 -> 160 | H2: =MAX(G2-E2,0) -> 88 | I2: {=_xlfn.XLOOKUP(C2,Supplier!$A:$A,Supplier!$C:$D)} -> Rana.Dubey@union.com | J2: 8164557242 | K2: =D2*H2 -> 6878.96
A3: SKU205 | B3: Desk Lamp | C3: BritGoods Ltd | D3: 17.41 | E3: 36 | F3: 65 | G3: =F3*2 -> 130 | H3: =MAX(G3-E3,0) -> 94 | I3: {=_xlfn.XLOOKUP(C3,Supplier!$A:$A,Supplier!$C:$D)} -> Adam.Francis@britgoods.com | J3: 8707063874 | K3: =D3*H3 -> 1636.54
A4: SKU213 | B4: X-Phone Case | C4: BritGoods Ltd | D4: 86.07 | E4: 15 | F4: 20 | G4: =F4*2 -> 40 | H4: =MAX(G4-E4,0) -> 25 | I4: {=_xlfn.XLOOKUP(C4,Supplier!$A:$A,Supplier!$C:$D)} -> Adam.Francis@britgoods.com | J4: 8707063874 | K4: =D4*H4 -> 2151.75
A5: SKU214 | B5: LED Monitor | C5: BritGoods Ltd | D5: 66.78 | E5: 49 | F5: 54 | G5: =F5*2 -> 108 | H5: =MAX(G5-E5,0) -> 59 | I5: {=_xlfn.XLOOKUP(C5,Supplier!$A:$A,Supplier!$C:$D)} -> Adam.Francis@britgoods.com | J5: 8707063874 | K5: =D5*H5 -> 3940.02
A6: SKU217 | B6: X-Phone Case | C6: Westfield Distributors | D6: 68.39 | E6: 41 | F6: 79 | G6: =F6*2 -> 158 | H6: =MAX(G6-E6,0) -> 117 | I6: {=_xlfn.XLOOKUP(C6,Supplier!$A:$A,Supplier!$C:$D)} -> Connor.Diabolic@westfield.com | J6: 7078282595 | K6: =D6*H6 -> 8001.63
A7: SKU218 | B7: Oak Desk | C7: Crown Suppliers | D7: 93.12 | E7: 15 | F7: 23 | G7: =F7*2 -> 46 | H7: =MAX(G7-E7,0) -> 31 | I7: {=_xlfn.XLOOKUP(C7,Supplier!$A:$A,Supplier!$C:$D)} -> Tia.McMillian@crown.com | J7: 8487915906 | K7: =D7*H7 -> 2886.72
A8: SKU219 | B8: Cotton Shirt | C8: Crown Suppliers | D8: 85.06 | E8: 41 | F8: 72 | G8: =F8*2 -> 144 | H8: =MAX(G8-E8,0) -> 103 | I8: {=_xlfn.XLOOKUP(C8,Supplier!$A:$A,Supplier!$C:$D)} -> Tia.McMillian@crown.com | J8: 8487915906 | K8: =D8*H8 -> 8761.18
A9: SKU220 | B9: Cotton Shirt | C9: BritGoods Ltd | D9: 103.58 | E9: 45 | F9: 74 | G9: =F9*2 -> 148 | H9: =MAX(G9-E9,0) -> 103 | I9: {=_xlfn.XLOOKUP(C9,Supplier!$A:$A,Supplier!$C:$D)} -> Adam.Francis@britgoods.com | J9: 8707063874 | K9: =D9*H9 -> 10668.74
A10: SKU225 | B10: Desk Lamp | C10: NorthTech Supplies | D10: 4.59 | E10: 19 | F10: 32 | G10: =F10*2 -> 64 | H10: =MAX(G10-E10,0) -> 45 | I10: {=_xlfn.XLOOKUP(C10,Supplier!$A:$A,Supplier!$C:$D)} -> Fia.Ghazal@northtech.com | J10: 8496059877 | K10: =D10*H10 -> 206.55
A11: SKU230 | B11: Cotton Shirt | C11: Union Parts | D11: 61.44 | E11: 24 | F11: 61 | G11: =F11*2 -> 122 | H11: =MAX(G11-E11,0) -> 98 | I11: {=_xlfn.XLOOKUP(C11,Supplier!$A:$A,Supplier!$C:$D)} -> Rana.Dubey@union.com | J11: 8164557242 | K11: =D11*H11 -> 6021.12
A12: SKU232 | B12: Ergo Chair | C12: Westfield Distributors | D12: 33.07 | E12: 19 | F12: 59 | G12: =F12*2 -> 118 | H12: =MAX(G12-E12,0) -> 99 | I12: {=_xlfn.XLOOKUP(C12,Supplier!$A:$A,Supplier!$C:$D)} -> Connor.Diabolic@westfield.com | J12: 7078282595 | K12: =D12*H12 -> 3273.93

Sheet PivotTable Inventory
A1: Count of Item Code | D1: Row Labels | E1: Sum of Stock Quantity | G1: Row Labels | H1: Count of Low Stock
A2: 40 | D2: Cotton Shirt | E2: 864 | G2: Cotton Shirt | H2: 3
D3: Desk Lamp | E3: 412 | G3: Desk Lamp | H3: 2
A4: Total SKU | B4: =GETPIVOTDATA("Item Code",$A$1) -> 40 | D4: Ergo Chair | E4: 676 | G4: Ergo Chair | H4: 1
A5: Low Stock Item | B5: =COUNTIF(Inventory!H:H,"YES") -> 11 | D5: LED Monitor | E5: 712 | G5: LED Monitor | H5: 1
A6: Out of Stock | B6: =COUNTIF(Inventory!E:E,0) -> 0 | D6: Oak Desk | E6: 916 | G6: Oak Desk | H6: 1
A7: Average Lead Time | B7: =AVERAGE(Inventory!G:G) -> 13.5 | D7: Thermal Jacket | E7: 318 | G7: Thermal Jacket | H7: 1
A8: Total Reoder cost | B8: =GETPIVOTDATA("Total Order Value",'Pivot Table Reorder'!$A$3) -> 54427.14 | D8: Wireless Mouse | E8: 511 | G8: X-Phone Case | H8: 2
D9: X-Phone Case | E9: 166 | G9: Grand Total | H9: 11
D10: Grand Total | E10: 4575
D13: Row Labels | E13: Average of Lead Time (days) | G13: Row Labels | H13: Sum of Stock Quantity | I13: Sum of Reorder Point
D14: BritGoods Ltd | E14: 13.2 | G14: Cotton Shirt | H14: 864 | I14: 492
D15: Crown Suppliers | E15: 15.25 | G15: Desk Lamp | H15: 412 | I15: 145
D16: NorthTech Supplies | E16: 12.555556 | G16: Ergo Chair | H16: 676 | I16: 261
D17: Union Parts | E17: 13 | G17: LED Monitor | H17: 712 | I17: 306
D18: Westfield Distributors | E18: 13.571429 | G18: Oak Desk | H18: 916 | I18: 425
D19: Grand Total | E19: 13.5 | G19: Thermal Jacket | H19: 318 | I19: 134
G20: Wireless Mouse | H20: 511 | I20: 134
G21: X-Phone Case | H21: 166 | I21: 146
G22: Grand Total | H22: 4575 | I22: 2043

Sheet Pivot Table Reorder
A3: Row Labels | B3: Sum of Total Order Value | D3: Row Labels | E3: Sum of Total Order Value
A4: Cotton Shirt | B4: 25451.04 | D4: BritGoods Ltd | E4: 18397.05
A5: Desk Lamp | B5: 1843.09 | D5: Crown Suppliers | E5: 11647.9
A6: Ergo Chair | B6: 3273.93 | D6: NorthTech Supplies | E6: 206.55
A7: LED Monitor | B7: 3940.02 | D7: Union Parts | E7: 12900.08
A8: Oak Desk | B8: 2886.72 | D8: Westfield Distributors | E8: 11275.56
A9: Thermal Jacket | B9: 6878.96 | D9: Grand Total | E9: 54427.14
A10: X-Phone Case | B10: 10153.38
A11: Grand Total | B11: 54427.14

Sheet Dashboard
