Workbook

Sheet Instructions
A1: Instructions
A2: Data_Cleaning_Practice.xlsx - Instructions
A4: Sheets:
A5: - DirtyData: Messy customer orders with inconsistent names, date formats, duplicates, and missing values.
A6: Suggested tasks:
A7: - Normalize customer names (trim, proper case), fix emails and remove duplicates.
A8: - Convert Order Date into consistent DD/MM/YYYY format (use Power Query or DATEVALUE + TEXT).
A9: - Fill missing Order Value where possible or flag them.
A10: - Produce a cleaned master table and a summary of total orders per customer.

Sheet DirtyData
A1: Customer ID | B1: Customer Name | C1: Email | D1: Order Date | E1: Order Value (£)
A2: C1000 | B2: Katie lee | C2: katie.lee@example.co.uk | D2: 2024-04-20 | E2: 808.68
A3: C1001 | B3: Isabel Oconnor | C3: isabel.oconnor@example.co.uk | D3: 2024-10-01 | E3: 329.06
A4: C1002 | B4: G. Harris | C4: gharris@example.co.uk | D4: 19-Aug-2024
A5: C1003 | B5: Katie lee | C5: katie.lee@example.co.uk | D5: 12-Sep-2024 | E5: 745.19
A6: C1004 | B6: bob taylor | C6: bob.taylor@example.co.uk | D6: 2024-09-28 | E6: 143.93
A7: C1005 | B7: Isabel Oconnor | C7: isabel.oconnor@example.co.uk | D7: 19-Dec-2024 | E7: 972.03
A8: C1006 | B8: Katie lee | C8: katie.lee@example.co.uk | D8: 06-Oct-2024 | E8: 771.61
A9: C1007 | B9: Fiona-lee | C9: fiona@example.co.uk | D9: 2024-01-06 | E9: 176.05
A10: C1008 | B10: Ethan Smith | D10: 2024-09-06 | E10: 646.22
A11: C1009 | B11: DEBORAH O'NEIL | C11: deborah.oneil@example.co.uk | D11: 28-Apr-2024 | E11: 967.35
A12: C1010 | B12: Jack O'Brien | C12: jackobrien@example.co.uk | D12: 27-May-2024 | E12: 1193.86
A13: C1011 | B13: DEBORAH O'NEIL | C13: deborah.oneil@example.co.uk | D13: 01/06/2024
A14: C1012 | B14: G. Harris | C14: gharris@example.co.uk | D14: 12-Oct-2024 | E14: 251.93
A15: C1013 | B15: G. Harris | C15: gharris@example.co.uk | D15: 2024-04-27 | E15: 1174.71
A16: C1014 | B16: Ethan Smith | D16: 24/08/2024 | E16: 787.82
A17: C1015 | B17: ALICE GREEN | C17: alice.green@example.co.uk | D17: 23/06/2024 | E17: 66.65
A18: C1016 | B18: ETHAN SMITH | D18: 09-Aug-2024 | E18: 418.1
A19: C1017 | B19: G. Harris | C19: gharris@example.co.uk | D19: 13/01/2024 | E19: 947
A20: C1018 | B20: Fiona-lee | C20: fiona@example.co.uk | D20: 14/06/2024 | E20: 229.24
A21: C1019 | B21: Alice Green | C21: alice.green@example.co.uk | D21: 2024-11-10 | E21: 953.82
A22: C1020 | B22: G. Harris | C22: gharris@example.co.uk | D22: 20/06/2024 | E22: 724.93
A23: C1021 | B23: Deborah O'Neil | C23: deborah.oneil@example.co.uk | D23: 2024-02-05 | E23: 406.29
A24: C1022 | B24: KATIE LEE | C24: katie.lee@example.co.uk | D24: 06/11/2024 | E24: 1117.32
A25: C1023 | B25: Isabel Oconnor | C25: isabel.oconnor@example.co.uk | D25: 16/08/2024 | E25: 516.46
A26: C1024 | B26: Deborah O'Neil | C26: deborah.oneil@example.co.uk | D26: 2024-06-18 | E26: 213.45
A27: C1025 | B27: FIONA-LEE | C27: fiona@example.co.uk | D27: 2024-02-17 | E27: 592.21
A28: C1026 | B28: Alice Green | C28: alice.green@example.co.uk | D28: 2024-01-12 | E28: 723.15
A29: C1027 | B29: Ethan Smith | D29: 25/06/2024 | E29: 364.1
A30: C1028 | B30: ETHAN SMITH | D30: 2024-06-19 | E30: 845.77
A31: C1029 | B31: Ethan Smith | D31: 2024-06-08
A32: C1030 | B32: Jack O'Brien | C32: jackobrien@example.co.uk | D32: 07/12/2024 | E32: 992.34
A33: C1031 | B33: charles KING | C33: charles.king@example.co.uk | D33: 06-Sep-2024 | E33: 91.3
A34: C1032 | B34: ISABEL OCONNOR | C34: isabel.oconnor@example.co.uk | D34: 11-Mar-2024 | E34: 84.49
A35: C1033 | B35: Ethan Smith | D35: 24/06/2024 | E35: 584.33
A36: C1034 | B36: bob taylor | C36: bob.taylor@example.co.uk | D36: 16/11/2024 | E36: 358.12
A37: C1035 | B37: Isabel Oconnor | C37: isabel.oconnor@example.co.uk | D37: 19/07/2024 | E37: 1184.45
A38: C1036 | B38: charles KING | C38: charles.king@example.co.uk | D38: 2024-11-26 | E38: 321.77
A39: C1037 | B39: Katie lee | C39: katie.lee@example.co.uk | D39: 02-Feb-2024 | E39: 718.74
A40: C1038 | B40: Alice Green | C40: alice.green@example.co.uk | D40: 11/12/2024 | E40: 123.29
...

Sheet Clean Data with Powe Query
A1: Customer ID | B1: Customer Name | C1: Email | D1: Order Date | E1: Order Value (£)
A2: C1000 | B2: Katie Lee | C2: katie.lee@example.co.uk | D2: 45402 | E2: 808.68
A3: C1001 | B3: Isabel Oconnor | C3: isabel.oconnor@example.co.uk | D3: 45566 | E3: 329.06
A4: C1003 | B4: Katie Lee | C4: katie.lee@example.co.uk | D4: 45547 | E4: 745.19
A5: C1004 | B5: Bob Taylor | C5: bob.taylor@example.co.uk | D5: 45563 | E5: 143.93
A6: C1005 | B6: Isabel Oconnor | C6: isabel.oconnor@example.co.uk | D6: 45645 | E6: 972.03
A7: C1006 | B7: Katie Lee | C7: katie.lee@example.co.uk | D7: 45571 | E7: 771.61
A8: C1007 | B8: Fiona Lee | C8: fiona@example.co.uk | D8: 45297 | E8: 176.05
A9: C1008 | B9: Ethan Smith | C9: ethan@example.co.uk | D9: 45541 | E9: 646.22
A10: C1009 | B10: Deborah O'Neil | C10: deborah.oneil@example.co.uk | D10: 45410 | E10: 967.35
A11: C1010 | B11: Jack O'Brien | C11: jackobrien@example.co.uk | D11: 45439 | E11: 1193.86
A12: C1012 | B12: G. Harris | C12: gharris@example.co.uk | D12: 45577 | E12: 251.93
A13: C1013 | B13: G. Harris | C13: gharris@example.co.uk | D13: 45409 | E13: 1174.71
... A58: C2000 | B58: Alice Green | C58: alice.green@example.co.uk | D58: 45413 | E58: 250

Sheet Clean Data Manually
A1: Customer ID | B1: Customer Name | C1: Email | D1: Order Date | E1: Order Value (£)
A2: C1000 | B2: Katie Lee | C2: katie.lee@example.co.uk | D2: 45402 | E2: 808.68
A3: C1001 | B3: Isabel Oconnor | C3: isabel.oconnor@example.co.uk | D3: 45566 | E3: 329.06
A4: C1003 | B4: Katie Lee | C4: katie.lee@example.co.uk | D4: 45547 | E4: 745.19
A5: C1004 | B5: Bob Taylor | C5: bob.taylor@example.co.uk | D5: 45563 | E5: 143.93
A6: C1005 | B6: Isabel Oconnor | C6: isabel.oconnor@example.co.uk | D6: 45645 | E6: 972.03
A7: C1006 | B7: Katie Lee | C7: katie.lee@example.co.uk | D7: 45571 | E7: 771.61
A8: C1007 | B8: Fiona-Lee | C8: fiona@example.co.uk | D8: 45297 | E8: 176.05
A9: C1008 | B9: Ethan Smith | C9: ethan.smith@example.co.uk | D9: 45541 | E9: 646.22
A10: C1009 | B10: Deborah O'Neil | C10: deborah.oneil@example.co.uk | D10: 45410 | E10: 967.35
A11: C1010 | B11: Jack O'Brien | C11: jackobrien@example.co.uk | D11: 45439 | E11: 1193.86
A12: C1012 | B12: G. Harris | C12: gharris@example.co.uk | D12: 45577 | E12: 251.93
A13: C1013 | B13: G. Harris | C13: gharris@example.co.uk | D13: 45409 | E13: 1174.71
... A59: C2001 | B59: Alice Green | C59: alice.green@example.co.uk | D59: 45413 | E59: 250

Sheet Summary
A1: Customer Name | B1: Email | C1: Total Order | D1: Total Value
A2: Charles King | B2: =_xlfn.XLOOKUP(A2,Table4[Customer Name],Table4[Email]) -> charles.king@example.co.uk | C2: =COUNTIF(Table4[Customer Name],Summary!A11) -> 7 | D2: =SUMIF(Table4[Customer Name],Summary!A11,Table4[Order Value (£)]) -> 4819.76
A3: Alice Green | B3: =_xlfn.XLOOKUP(A3,Table4[Customer Name],Table4[Email]) -> alice.green@example.co.uk | C3: =COUNTIF(Table4[Customer Name],Summary!A10) -> 6 | D3: =SUMIF(Table4[Customer Name],Summary!A10,Table4[Order Value (£)]) -> 4186.42
A4: G. Harris | B4: =_xlfn.XLOOKUP(A4,Table4[Customer Name],Table4[Email]) -> gharris@example.co.uk | C4: =COUNTIF(Table4[Customer Name],Summary!A9) -> 5 | D4: =SUMIF(Table4[Customer Name],Summary!A9,Table4[Order Value (£)]) -> 3174.23
A5: Jack O'Brien | B5: =_xlfn.XLOOKUP(A5,Table4[Customer Name],Table4[Email]) -> jackobrien@example.co.uk | C5: =COUNTIF(Table4[Customer Name],Summary!A8) -> 4 | D5: =SUMIF(Table4[Customer Name],Summary!A8,Table4[Order Value (£)]) -> 1021.65
A6: Deborah O'Neil | B6: =_xlfn.XLOOKUP(A6,Table4[Customer Name],Table4[Email]) -> deborah.oneil@example.co.uk | C6: =COUNTIF(Table4[Customer Name],Summary!A7) -> 6 | D6: =SUMIF(Table4[Customer Name],Summary!A7,Table4[Order Value (£)]) -> 3646.34
A7: Ethan Smith | B7: =_xlfn.XLOOKUP(A7,Table4[Customer Name],Table4[Email]) -> ethan.smith@example.co.uk | C7: =COUNTIF(Table4[Customer Name],Summary!A6) -> 5 | D7: =SUMIF(Table4[Customer Name],Summary!A6,Table4[Order Value (£)]) -> 3113.16
A8: Fiona-Lee | B8: =_xlfn.XLOOKUP(A8,Table4[Customer Name],Table4[Email]) -> fiona@example.co.uk | C8: =COUNTIF(Table4[Customer Name],Summary!A5) -> 6 | D8: =SUMIF(Table4[Customer Name],Summary!A5,Table4[Order Value (£)]) -> 4285.08
A9: Bob Taylor | B9: =_xlfn.XLOOKUP(A9,Table4[Customer Name],Table4[Email]) -> bob.taylor@example.co.uk | C9: =COUNTIF(Table4[Customer Name],Summary!A4) -> 7 | D9: =SUMIF(Table4[Customer Name],Summary!A4,Table4[Order Value (£)]) -> 4827.1
A10: Isabel Oconnor | B10: =_xlfn.XLOOKUP(A10,Table4[Customer Name],Table4[Email]) -> isabel.oconnor@example.co.uk | C10: =COUNTIF(Table4[Customer Name],Summary!A3) -> 8 | D10: =SUMIF(Table4[Customer Name],Summary!A3,Table4[Order Value (£)]) -> 3937.31
A11: Katie Lee | B11: =_xlfn.XLOOKUP(A11,Table4[Customer Name],Table4[Email]) -> katie.lee@example.co.uk | C11: =COUNTIF(Table4[Customer Name],Summary!A2) -> 4 | D11: =SUMIF(Table4[Customer Name],Summary!A2,Table4[Order Value (£)]) -> 2316.06

Sheet Documentation
C37: Issue | F37: Before | I37: After
C38: Name Spacing | F38: Katie Lee | I38: Katie Lee
C39: Text Currency | F39: 808.08 | I39: 808.08
C40: Text Date | F40: 45402 | I40: 45402
C41: Email Format | F41: Katie.LEE@Example.cO.Uk | I41: Katie.lee@example.co.uk
C42: Dublicate Rows | F42: Bob Taylor (2x) | I42: Bob Taylor (Unique)
C43: Customer ID outlier | F43: C2000, C2001 | I43: Standardize format
